The test result indicates that there was a failure in the test named test_list_fraction within the TestSum class. Let's break down the information provided:

Test Description: The test is designed to check whether the sum function can correctly sum a list of fractions.

Traceback: The traceback provides information about where the failure occurred. In this case, it points to line 22 of the test.py file in the test_list_fraction method.

AssertionError: The assertEqual assertion failed. It expected the result of the sum function, which is a Fraction(9, 10), to be equal to 1. However, the actual result was not 1.

Test Execution Time: The tests were executed in 0.002 seconds.

Overall Result: The test run resulted in 2 tests being executed, with 1 failure (FAILED (failures=1)).

The failure indicates that the sum function did not produce the expected result when summing a list of fractions. Specifically, the sum of [Fraction(1, 4), Fraction(1, 4), Fraction(2, 5)] is Fraction(9, 10), which is not equal to 1 as asserted in the test.
To address this issue, you may need to review and modify the implementation of the sum function to correctly handle fractions or adjust the expected result in the test case. Additionally, this failure highlights the importance of thorough testing,         especially when dealing with different data types or scenarios.
In summary, the failed test result serves as a valuable indicator of potential issues in the code and prompts further investigation and refinement of the tested functionality.
